Workbook

Sheet SP500_Clean
A1: observation_date | B1: SP500 | C1: Daily_Return | D1: Month | E1: Column1 | F1: Monthly_Return
A2: 44476 | B2: 4399.76 | D2: =MONTH(tbl_SP500_Clean[[#This Row],[observation_date]]) -> 10 | E2: =IF(D2<>D3,"Yes","No") -> No
A3: 44477 | B3: 4391.34 | C3: =(B3-B2)/B2 -> -0.0019137407 | D3: =MONTH(tbl_SP500_Clean[[#This Row],[observation_date]]) -> 10 | E3: =IF(D3<>D4,"Yes","No") -> No
A4: 44480 | B4: 4361.19 | C4: =(B4-B3)/B3 -> -0.0068657858 | D4: =MONTH(tbl_SP500_Clean[[#This Row],[observation_date]]) -> 10 | E4: =IF(D4<>D5,"Yes","No") -> No | F4: =COUNTBLANK(tbl_SP500_Clean[SP500]) -> 50
A5: 44481 | B5: 4350.65 | C5: =(B5-B4)/B4 -> -0.0024167716 | D5: =MONTH(tbl_SP500_Clean[[#This Row],[observation_date]]) -> 10 | E5: =IF(D5<>D6,"Yes","No") -> No
A6: 44482 | B6: 4363.8 | C6: =(B6-B5)/B5 -> 0.0030225369 | D6: =MONTH(tbl_SP500_Clean[[#This Row],[observation_date]]) -> 10 | E6: =IF(D6<>D7,"Yes","No") -> No
A7: 44483 | B7: 4438.26 | C7: =(B7-B6)/B6 -> 0.01706311 | D7: =MONTH(tbl_SP500_Clean[[#This Row],[observation_date]]) -> 10 | E7: =IF(D7<>D8,"Yes","No") -> No
A8: 44484 | B8: 4471.37 | C8: =(B8-B7)/B7 -> 0.0074601308 | D8: =MONTH(tbl_SP500_Clean[[#This Row],[observation_date]]) -> 10 | E8: =IF(D8<>D9,"Yes","No") -> No
A9: 44487 | B9: 4486.46 | C9: =(B9-B8)/B8 -> 0.0033748046 | D9: =MONTH(tbl_SP500_Clean[[#This Row],[observation_date]]) -> 10 | E9: =IF(D9<>D10,"Yes","No") -> No
A10: 44488 | B10: 4519.63 | C10: =(B10-B9)/B9 -> 0.0073933569 | D10: =MONTH(tbl_SP500_Clean[[#This Row],[observation_date]]) -> 10 | E10: =IF(D10<>D11,"Yes","No") -> No
A11: 44489 | B11: 4536.19 | C11: =(B11-B10)/B10 -> 0.0036640167 | D11: =MONTH(tbl_SP500_Clean[[#This Row],[observation_date]]) -> 10 | E11: =IF(D11<>D12,"Yes","No") -> No
A12: 44490 | B12: 4549.78 | C12: =(B12-B11)/B11 -> 0.0029959063 | D12: =MONTH(tbl_SP500_Clean[[#This Row],[observation_date]]) -> 10 | E12: =IF(D12<>D13,"Yes","No") -> No
A13: 44491 | B13: 4544.9 | C13: =(B13-B12)/B12 -> -0.0010725793 | D13: =MONTH(tbl_SP500_Clean[[#This Row],[observation_date]]) -> 10 | E13: =IF(D13<>D14,"Yes","No") -> No
A14: 44494 | B14: 4566.48 | C14: =(B14-B13)/B13 -> 0.0047481793 | D14: =MONTH(tbl_SP500_Clean[[#This Row],[observation_date]]) -> 10 | E14: =IF(D14<>D15,"Yes","No") -> No
A15: 44495 | B15: 4574.79 | C15: =(B15-B14)/B14 -> 0.0018197824 | D15: =MONTH(tbl_SP500_Clean[[#This Row],[observation_date]]) -> 10 | E15: =IF(D15<>D16,"Yes","No") -> No
A16: 44496 | B16: 4551.68 | C16: =(B16-B15)/B15 -> -0.005051598 | D16: =MONTH(tbl_SP500_Clean[[#This Row],[observation_date]]) -> 10 | E16: =IF(D16<>D17,"Yes","No") -> No
... A36: 44524 | B36: 4701.46 | C36: =(B36-B35)/B35 -> 0.0022939007 | D36: =MONTH(tbl_SP500_Clean[[#This Row],[observation_date]]) -> 11 | E36: =IF(D36<>D37,"Yes","No") -> No
A37: 44525 | C37: =(B37-B36)/B36 -> -1 | D37: =MONTH(tbl_SP500_Clean[[#This Row],[observation_date]]) -> 11 | E37: =IF(D37<>D38,"Yes","No") -> No
A38: 44526 | B38: 4594.62 | C38: =(B38-B37)/B37 -> #DIV/0! | D38: =MONTH(tbl_SP500_Clean[[#This Row],[observation_date]]) -> 11 | E38: =IF(D38<>D39,"Yes","No") -> No
A39: 44529 | B39: 4655.27 | C39: =(B39-B38)/B38 -> 0.013200221 | D39: =MONTH(tbl_SP500_Clean[[#This Row],[observation_date]]) -> 11 | E39: =IF(D39<>D40,"Yes","No") -> No
A40: 44530 | B40: 4567 | C40: =(B40-B39)/B39 -> -0.018961306 | D40: =MONTH(tbl_SP500_Clean[[#This Row],[observation_date]]) -> 11 | E40: =IF(D40<>D41,"Yes","No") -> Yes | F40: =(B40-B18)/B18 -> -0.0083337314
A41: 44531 | B41: 4513.04 | C41: =(B41-B40)/B40 -> -0.011815196 | D41: =MONTH(tbl_SP500_Clean[[#This Row],[observation_date]]) -> 12 | E41: =IF(D41<>D42,"Yes","No") -> No
A42: 44532 | B42: 4577.1 | C42: =(B42-B41)/B41 -> 0.014194423 | D42: =MONTH(tbl_SP500_Clean[[#This Row],[observation_date]]) -> 12 | E42: =IF(D42<>D43,"Yes","No") -> No
A43: 44533 | B43: 4538.43 | C43: =(B43-B42)/B42 -> -0.008448581 | D43: =MONTH(tbl_SP500_Clean[[#This Row],[observation_date]]) -> 12 | E43: =IF(D43<>D44,"Yes","No") -> No
A44: 44536 | B44: 4591.67 | C44: =(B44-B43)/B43 -> 0.011730929 | D44: =MONTH(tbl_SP500_Clean[[#This Row],[observation_date]]) -> 12 | E44: =IF(D44<>D45,"Yes","No") -> No
A45: 44537 | B45: 4686.75 | C45: =(B45-B44)/B44 -> 0.020707063 | D45: =MONTH(tbl_SP500_Clean[[#This Row],[observation_date]]) -> 12 | E45: =IF(D45<>D46,"Yes","No") -> No
A46: 44538 | B46: 4701.21 | C46: =(B46-B45)/B45 -> 0.0030852936 | D46: =MONTH(tbl_SP500_Clean[[#This Row],[observation_date]]) -> 12 | E46: =IF(D46<>D47,"Yes","No") -> No
A47: 44539 | B47: 4667.45 | C47: =(B47-B46)/B46 -> -0.00718113 | D47: =MONTH(tbl_SP500_Clean[[#This Row],[observation_date]]) -> 12 | E47: =IF(D47<>D48,"Yes","No") -> No
A48: 44540 | B48: 4712.02 | C48: =(B48-B47)/B47 -> 0.0095491114 | D48: =MONTH(tbl_SP500_Clean[[#This Row],[observation_date]]) -> 12 | E48: =IF(D48<>D49,"Yes","No") -> No
A49: 44543 | B49: 4668.97 | C49: =(B49-B48)/B48 -> -0.0091362091 | D49: =MONTH(tbl_SP500_Clean[[#This Row],[observation_date]]) -> 12 | E49: =IF(D49<>D50,"Yes","No") -> No
A50: 44544 | B50: 4634.09 | C50: =(B50-B49)/B49 -> -0.0074705984 | D50: =MONTH(tbl_SP500_Clean[[#This Row],[observation_date]]) -> 12 | E50: =IF(D50<>D51,"Yes","No") -> No
A51: 44545 | B51: 4709.85 | C51: =(B51-B50)/B50 -> 0.016348409 | D51: =MONTH(tbl_SP500_Clean[[#This Row],[observation_date]]) -> 12 | E51: =IF(D51<>D52,"Yes","No") -> No
A52: 44546 | B52: 4668.67 | C52: =(B52-B51)/B51 -> -0.0087433782 | D52: =MONTH(tbl_SP500_Clean[[#This Row],[observation_date]]) -> 12 | E52: =IF(D52<>D53,"Yes","No") -> No
... A57: 44553 | B57: 4725.79 | C57: =(B57-B56)/B56 -> 0.0062237042 | D57: =MONTH(tbl_SP500_Clean[[#This Row],[observation_date]]) -> 12 | E57: =IF(D57<>D58,"Yes","No") -> No
A58: 44554 | C58: =(B58-B57)/B57 -> -1 | D58: =MONTH(tbl_SP500_Clean[[#This Row],[observation_date]]) -> 12 | E58: =IF(D58<>D59,"Yes","No") -> No
A59: 44557 | B59: 4791.19 | C59: =(B59-B58)/B58 -> #DIV/0! | D59: =MONTH(tbl_SP500_Clean[[#This Row],[observation_date]]) -> 12 | E59: =IF(D59<>D60,"Yes","No") -> No
A60: 44558 | B60: 4786.35 | C60: =(B60-B59)/B59 -> -0.0010101874 | D60: =MONTH(tbl_SP500_Clean[[#This Row],[observation_date]]) -> 12 | E60: =IF(D60<>D61,"Yes","No") -> No
A61: 44559 | B61: 4793.06 | C61: =(B61-B60)/B60 -> 0.0014019033 | D61: =MONTH(tbl_SP500_Clean[[#This Row],[observation_date]]) -> 12 | E61: =IF(D61<>D62,"Yes","No") -> No
A62: 44560 | B62: 4778.73 | C62: =(B62-B61)/B61 -> -0.0029897393 | D62: =MONTH(tbl_SP500_Clean[[#This Row],[observation_date]]) -> 12 | E62: =IF(D62<>D63,"Yes","No") -> No
A63: 44561 | B63: 4766.18 | C63: =(B63-B62)/B62 -> -0.0026262208 | D63: =MONTH(tbl_SP500_Clean[[#This Row],[observation_date]]) -> 12 | E63: =IF(D63<>D64,"Yes","No") -> Yes | F63: =(B63-B40)/B40 -> 0.043612875
...

Sheet SP500_Monthly
A1: observation_date | B1: SP500 | C1: Monthly_Return | D1: Investment_Value | E1: Dynamic_Investment_Value
A2: 44498 | B2: 4605.38 | D2: 1000 | E2: =Performance_Summary!$E$5*(B2/$B$2) -> 200
A3: 44530 | B3: 4567 | C3: =(B3-B2)/B2 -> -0.0083337314 | D3: =D2*(1+C3) -> 991.66627 | E3: =Performance_Summary!$E$5*(B3/$B$2) -> 198.33325 | F3: =(D16-D4)/D4 -> -0.19442824
A4: 44561 | B4: 4766.18 | C4: =(B4-B3)/B3 -> 0.043612875 | D4: =D3*(1+C4) -> 1034.9157 | E4: =Performance_Summary!$E$5*(B4/$B$2) -> 206.98314
A5: 44592 | B5: 4515.55 | C5: =(B5-B4)/B4 -> -0.052585089 | D5: =D4*(1+C5) -> 980.49455 | E5: =Performance_Summary!$E$5*(B5/$B$2) -> 196.09891
A6: 44620 | B6: 4373.94 | C6: =(B6-B5)/B5 -> -0.031360521 | D6: =D5*(1+C6) -> 949.74573 | E6: =Performance_Summary!$E$5*(B6/$B$2) -> 189.94915
A7: 44651 | B7: 4530.41 | C7: =(B7-B6)/B6 -> 0.035773239 | D7: =D6*(1+C7) -> 983.72121 | E7: =Performance_Summary!$E$5*(B7/$B$2) -> 196.74424
A8: 44680 | B8: 4131.93 | C8: =(B8-B7)/B7 -> -0.087956719 | D8: =D7*(1+C8) -> 897.19632 | E8: =Performance_Summary!$E$5*(B8/$B$2) -> 179.43926
A9: 44712 | B9: 4132.15 | C9: =(B9-B8)/B8 -> 5.3243884e-05 | D9: =D8*(1+C9) -> 897.24409 | E9: =Performance_Summary!$E$5*(B9/$B$2) -> 179.44882
A10: 44742 | B10: 3785.38 | C10: =(B10-B9)/B9 -> -0.083919993 | D10: =D9*(1+C10) -> 821.94737 | E10: =Performance_Summary!$E$5*(B10/$B$2) -> 164.38947
A11: 44771 | B11: 4130.29 | C11: =(B11-B10)/B10 -> 0.091116348 | D11: =D10*(1+C11) -> 896.84022 | E11: =Performance_Summary!$E$5*(B11/$B$2) -> 179.36804
A12: 44804 | B12: 3955 | C12: =(B12-B11)/B11 -> -0.042440119 | D12: =D11*(1+C12) -> 858.77821 | E12: =Performance_Summary!$E$5*(B12/$B$2) -> 171.75564
A13: 44834 | B13: 3585.62 | C13: =(B13-B12)/B12 -> -0.093395702 | D13: =D12*(1+C13) -> 778.57202 | E13: =Performance_Summary!$E$5*(B13/$B$2) -> 155.7144
A14: 44865 | B14: 3871.98 | C14: =(B14-B13)/B13 -> 0.079863455 | D14: =D13*(1+C14) -> 840.75147 | E14: =Performance_Summary!$E$5*(B14/$B$2) -> 168.15029
A15: 44895 | B15: 4080.11 | C15: =(B15-B14)/B14 -> 0.05375286 | D15: =D14*(1+C15) -> 885.94427 | E15: =Performance_Summary!$E$5*(B15/$B$2) -> 177.18885
... A60: 46295 | B60: 7651.54 | C60: =(B60-B59)/B59 -> -0.0045016094 | D60: =D59*(1+C60) -> 1661.4351 | E60: =Performance_Summary!$E$5*(B60/$B$2) -> 332.28702

Sheet VOO_Monthly
A1: Date | B1: Open | C1: High | D1: Low | E1: Close | F1: Volume | G1: Monthly_Return
A2: 44500 | B2: 377.163 | C2: 402.193 | D2: 373.108 | E2: 401.856 | F2: 98638768 | I2: Initial Investment | J2: 1000
A3: 44530 | B3: 402.825 | C3: 414.463 | D3: 398.493 | E3: 398.906 | F3: 1.053192e+08 | G3: =E3/E2-1 -> -0.007340938 | I3: Final Investment Value | J3: =J2+((E61-E2)/E2)*J2 -> 1744.0576 | L3: =E61-E2 -> 299.004
A4: 44561 | B4: 404.051 | C4: 420.714 | D4: 392.913 | E4: 417.09 | F4: 1.4942105e+08 | G4: =E4/E3-1 -> 0.045584674 | I4: Total Profit | J4: =J3-J2 -> 744.05757
A5: 44592 | B5: 418.392 | C5: 421.576 | D5: 369.58 | E5: 395.232 | F5: 2.1922423e+08 | G5: =E5/E4-1 -> -0.052405956 | I5: Total Return | J5: =J4/J2 -> 0.74405757
A6: 44620 | B6: 395.857 | C6: 402.395 | D6: 360.657 | E6: 383.453 | F6: 1.8647208e+08 | G6: =E6/E5-1 -> -0.029802749
A7: 44651 | B7: 382.167 | C7: 407.14 | D7: 364.615 | E7: 397.984 | F7: 1.4352545e+08 | G7: =E7/E6-1 -> 0.037895127 | I7: Best Monthly Return | J7: =MAX(G3:G61) -> 0.10548071
A8: 44681 | B8: 399.432 | C8: 403.401 | D8: 362.353 | E8: 363.025 | F8: 1.1444953e+08 | G8: =E8/E7-1 -> -0.087840215 | I8: Worst Monthly Return | J8: =MIN(G3:G61) -> -0.091988419
A9: 44712 | B9: 363.11 | C9: 378.578 | D9: 335.28 | E9: 363.964 | F9: 1.4899991e+08 | G9: =E9/E8-1 -> 0.0025865987
A10: 44742 | B10: 365.861 | C10: 367.856 | D10: 320.405 | E10: 333.885 | F10: 1.2353028e+08 | G10: =E10/E9-1 -> -0.082642789
A11: 44773 | B11: 333.191 | C11: 365.436 | D11: 328.267 | E11: 364.598 | F11: 95079818 | G11: =E11/E10-1 -> 0.091986762
A12: 44804 | B12: 362.029 | C12: 382.02 | D12: 349.507 | E12: 349.544 | F12: 86163299 | G12: =E12/E11-1 -> -0.04128931
A13: 44834 | B13: 347.572 | C13: 364.33 | D13: 317.217 | E13: 317.39 | F13: 1.1434638e+08 | G13: =E13/E12-1 -> -0.091988419
A14: 44865 | B14: 320.765 | C14: 346.085 | D14: 309.241 | E14: 343.155 | F14: 1.0258163e+08 | G14: =E14/E13-1 -> 0.081177731
A15: 44895 | B15: 346.616 | C15: 362.141 | D15: 327.639 | E15: 362.045 | F15: 81571155 | G15: =E15/E14-1 -> 0.05504801
A16: 44926 | B16: 363.38 | C16: 364.655 | D16: 334.491 | E16: 341.292 | F16: 97213663 | G16: =E16/E15-1 -> -0.057321604
A17: 44957 | B17: 343.079 | C17: 364.351 | D17: 337.26 | E17: 362.758 | F17: 78888171 | G17: =E17/E16-1 -> 0.062896288
A18: 44985 | B18: 361.786 | C18: 373.414 | D18: 351.384 | E18: 353.696 | F18: 72711336 | G18: =E18/E17-1 -> -0.024980841
A19: 45016 | B19: 352.948 | C19: 367.081 | D19: 339.755 | E19: 366.818 | F19: 1.0173095e+08 | G19: =E19/E18-1 -> 0.037099656
A20: 45046 | B20: 366.359 | C20: 372.719 | D20: 361.852 | E20: 372.652 | F20: 60753037 | G20: =E20/E19-1 -> 0.015904345
... A61: 46295 | B61: 700.45 | C61: 714.3 | D61: 689.04 | E61: 700.86 | F61: 200315333 | G61: =E61/E60-1 -> -0.0057172041

Sheet VOO_Raw
A1: Date | B1: Open | C1: High | D1: Low | E1: Close | F1: Volume
A2: 44500 | B2: 377.163 | C2: 402.193 | D2: 373.108 | E2: 401.856 | F2: 98638768
A3: 44530 | B3: 402.825 | C3: 414.463 | D3: 398.493 | E3: 398.906 | F3: 1.053192e+08
A4: 44561 | B4: 404.051 | C4: 420.714 | D4: 392.913 | E4: 417.09 | F4: 1.4942105e+08
A5: 44592 | B5: 418.392 | C5: 421.576 | D5: 369.58 | E5: 395.232 | F5: 2.1922423e+08
A6: 44620 | B6: 395.857 | C6: 402.395 | D6: 360.657 | E6: 383.453 | F6: 1.8647208e+08
A7: 44651 | B7: 382.167 | C7: 407.14 | D7: 364.615 | E7: 397.984 | F7: 1.4352545e+08
A8: 44681 | B8: 399.432 | C8: 403.401 | D8: 362.353 | E8: 363.025 | F8: 1.1444953e+08
A9: 44712 | B9: 363.11 | C9: 378.578 | D9: 335.28 | E9: 363.964 | F9: 1.4899991e+08
A10: 44742 | B10: 365.861 | C10: 367.856 | D10: 320.405 | E10: 333.885 | F10: 1.2353028e+08
A11: 44773 | B11: 333.191 | C11: 365.436 | D11: 328.267 | E11: 364.598 | F11: 95079818
A12: 44804 | B12: 362.029 | C12: 382.02 | D12: 349.507 | E12: 349.544 | F12: 86163299
A13: 44834 | B13: 347.572 | C13: 364.33 | D13: 317.217 | E13: 317.39 | F13: 1.1434638e+08
... A61: 46295 | B61: 700.45 | C61: 714.3 | D61: 689.04 | E61: 700.86 | F61: 200315333

Sheet Performance_Summary
A1: Investment Performance Summary
D2: S&P 500 | T2: VOO vs. S&P 500
A3: Initial Investment | B3: =SP500_Monthly!D2 -> 1000 | D3: Investment Calculator | H3: Future Investment Projection | K3: Year | L3: Projected Value | N3: Monthly Contribution Calculator | Q3: 401(k) Retirement Summary | T3: VOO Total Return | U3: =VOO_Monthly!J5 -> 0.74405757
A4: Final Investment Value | B4: =SP500_Monthly!D60 -> 1661.4351 | K4: =0 -> 0 | L4: =IF(ISNUMBER(K4),$I$5*(1+$I$6)^K4,"") -> 200 | T4: S&P 500 Total Return | U4: =B6 -> 0.6614351
A5: Total Profit | B5: =B4-B3 -> 661.4351 | D5: Enter Investment Amount | E5: 200 | H5: Initial Investment | I5: =E5 -> 200 | K5: =IF(K4<$I$7,K4+1," ") -> 1 | L5: =IF(ISNUMBER(K5),$I$5*(1+$I$6)^K5,"") -> 214 | N5: Initial Investment | O5: =I5 -> 200 | Q5: Monthly Employee Contribution | R5: ='401K_Calculator'!E3 -> 400 | T5: Return Difference | U5: =U3-U4 -> 0.082622469
A6: Total Return (%) | B6: =B5/B3 -> 0.6614351 | H6: Expected Annual Return | I6: 0.07 | K6: =IF(K5<$I$7,K5+1," ") -> 2 | L6: =IF(ISNUMBER(K6),$I$5*(1+$I$6)^K6,"") -> 228.98 | N6: Monthly Contribution | O6: 200 | Q6: Monthly Employer Contribution | R6: ='401K_Calculator'!E4 -> 200
D7: Final Investment Value | E7: =E5*(1+$B$6) -> 332.28702 | H7: Investment Period (Years) | I7: 20 | K7: =IF(K6<$I$7,K6+1," ") -> 3 | L7: =IF(ISNUMBER(K7),$I$5*(1+$I$6)^K7,"") -> 245.0086 | N7: Expected Annual Return | O7: =I6 -> 0.07 | Q7: Total Monthly Contribution | R7: ='401K_Calculator'!E5 -> 600
A8: Best Monthly Return | B8: =MAX(SP500_Monthly!C3:C60) -> 0.10423343 | D8: Total Profit | E8: =E7-E5 -> 132.28702 | K8: =IF(K7<$I$7,K7+1," ") -> 4 | L8: =IF(ISNUMBER(K8),$I$5*(1+$I$6)^K8,"") -> 262.1592 | N8: Investment Period (Years) | O8: =I7 -> 20
A9: Worst Monthly Return | B9: =MIN(SP500_Monthly!C3:C60) -> -0.093395702 | D9: Total Return (%) | E9: =E8/E5 -> 0.6614351 | H9: Projected Future Value | I9: =FV(I6,I7,0,-I5) -> 773.93689 | K9: =IF(K8<$I$7,K8+1," ") -> 5 | L9: =IF(ISNUMBER(K9),$I$5*(1+$I$6)^K9,"") -> 280.51035 | Q9: Projected Retirement Balance | R9: ='401K_Calculator'!E7 -> 316594.73
A10: Best Performing Month | B10: =INDEX(SP500_Monthly!A3:A60,MATCH(B8,SP500_Monthly!C3:C60,0)) -> 46142 | H10: Projected Profit | I10: =I9-I5 -> 573.93689 | K10: =IF(K9<$I$7,K9+1," ") -> 6 | L10: =IF(ISNUMBER(K10),$I$5*(1+$I$6)^K10,"") -> 300.14607 | N10: Projected Future Value | O10: =FV(O7/12,O8*12,-O6,-O5) -> 104993.08 | Q10: Total Money Contributed | R10: ='401K_Calculator'!E8 -> 145000
A11: Worst Performing Month | B11: =INDEX(SP500_Monthly!A3:A60,MATCH(B9,SP500_Monthly!C3:C60,0)) -> 44834 | K11: =IF(K10<$I$7,K10+1," ") -> 7 | L11: =IF(ISNUMBER(K11),$I$5*(1+$I$6)^K11,"") -> 321.1563 | N11: Total Money Invested | O11: =O5+(O6*O8*12) -> 48200 | Q11: Projected Investment Growth | R11: ='401K_Calculator'!E9 -> 171594.73
K12: =IF(K11<$I$7,K11+1," ") -> 8 | L12: =IF(ISNUMBER(K12),$I$5*(1+$I$6)^K12,"") -> 343.63724 | N12: Projected Profit | O12: =O10-O11 -> 56793.08
K13: =IF(K12<$I$7,K12+1," ") -> 9 | L13: =IF(ISNUMBER(K13),$I$5*(1+$I$6)^K13,"") -> 367.69184
K14: =IF(K13<$I$7,K13+1," ") -> 10 | L14: =IF(ISNUMBER(K14),$I$5*(1+$I$6)^K14,"") -> 393.43027
K15: =IF(K14<$I$7,K14+1," ") -> 11 | L15: =IF(ISNUMBER(K15),$I$5*(1+$I$6)^K15,"") -> 420.97039
K16: =IF(K15<$I$7,K15+1," ") -> 12 | L16: =IF(ISNUMBER(K16),$I$5*(1+$I$6)^K16,"") -> 450.43832
K17: =IF(K16<$I$7,K16+1," ") -> 13 | L17: =IF(ISNUMBER(K17),$I$5*(1+$I$6)^K17,"") -> 481.969
K18: =IF(K17<$I$7,K17+1," ") -> 14 | L18: =IF(ISNUMBER(K18),$I$5*(1+$I$6)^K18,"") -> 515.70683
K19: =IF(K18<$I$7,K18+1," ") -> 15 | L19: =IF(ISNUMBER(K19),$I$5*(1+$I$6)^K19,"") -> 551.80631
K20: =IF(K19<$I$7,K19+1," ") -> 16 | L20: =IF(ISNUMBER(K20),$I$5*(1+$I$6)^K20,"") -> 590.43275
K21: =IF(K20<$I$7,K20+1," ") -> 17 | L21: =IF(ISNUMBER(K21),$I$5*(1+$I$6)^K21,"") -> 631.76304
K22: =IF(K21<$I$7,K21+1," ") -> 18 | L22: =IF(ISNUMBER(K22),$I$5*(1+$I$6)^K22,"") -> 675.98646
K23: =IF(K22<$I$7,K22+1," ") -> 19 | L23: =IF(ISNUMBER(K23),$I$5*(1+$I$6)^K23,"") -> 723.30551 | T23: VOO data: Stooq. S&P 500: index prices. Dividend adjustments may differ; returns are not directly comparable without verification.
K24: =IF(K23<$I$7,K23+1," ") -> 20 | L24: =IF(ISNUMBER(K24),$I$5*(1+$I$6)^K24,"") -> 773.93689
K25: =IF(K24<$I$7,K24+1," ") | L25: =IF(ISNUMBER(K25),$I$5*(1+$I$6)^K25,"")
K26: =IF(K25<$I$7,K25+1," ") | L26: =IF(ISNUMBER(K26),$I$5*(1+$I$6)^K26,"")
K27: =IF(K26<$I$7,K26+1," ") | L27: =IF(ISNUMBER(K27),$I$5*(1+$I$6)^K27,"")
K28: =IF(K27<$I$7,K27+1," ") | L28: =IF(ISNUMBER(K28),$I$5*(1+$I$6)^K28,"")
K29: =IF(K28<$I$7,K28+1," ") | L29: =IF(ISNUMBER(K29),$I$5*(1+$I$6)^K29,"")
K30: =IF(K29<$I$7,K29+1," ") | L30: =IF(ISNUMBER(K30),$I$5*(1+$I$6)^K30,"")
K31: =IF(K30<$I$7,K30+1," ") | L31: =IF(ISNUMBER(K31),$I$5*(1+$I$6)^K31,"")
K32: =IF(K31<$I$7,K31+1," ") | L32: =IF(ISNUMBER(K32),$I$5*(1+$I$6)^K32,"")
K33: =IF(K32<$I$7,K32+1," ") | L33: =IF(ISNUMBER(K33),$I$5*(1+$I$6)^K33,"")
K34: =IF(K33<$I$7,K33+1," ") | L34: =IF(ISNUMBER(K34),$I$5*(1+$I$6)^K34,"")
K35: =IF(K34<$I$7,K34+1," ") | L35: =IF(ISNUMBER(K35),$I$5*(1+$I$6)^K35,"")
... K54: =IF(K53<$I$7,K53+1," ") | L54: =IF(ISNUMBER(K54),$I$5*(1+$I$6)^K54,"")

Sheet SP500_Raw
A1: observation_date | B1: SP500
A2: 44476 | B2: 4399.76
A3: 44477 | B3: 4391.34
A4: 44480 | B4: 4361.19 | F4: =COUNTBLANK(tbl_SP500_Raw[SP500]) -> 50
A5: 44481 | B5: 4350.65
A6: 44482 | B6: 4363.8
A7: 44483 | B7: 4438.26
A8: 44484 | B8: 4471.37
A9: 44487 | B9: 4486.46
A10: 44488 | B10: 4519.63
A11: 44489 | B11: 4536.19
A12: 44490 | B12: 4549.78
A13: 44491 | B13: 4544.9
A14: 44494 | B14: 4566.48
A15: 44495 | B15: 4574.79
A16: 44496 | B16: 4551.68
... A36: 44524 | B36: 4701.46
A37: 44525
A38: 44526 | B38: 4594.62
A39: 44529 | B39: 4655.27
A40: 44530 | B40: 4567
A41: 44531 | B41: 4513.04
A42: 44532 | B42: 4577.1
A43: 44533 | B43: 4538.43
A44: 44536 | B44: 4591.67
A45: 44537 | B45: 4686.75
A46: 44538 | B46: 4701.21
A47: 44539 | B47: 4667.45
A48: 44540 | B48: 4712.02
A49: 44543 | B49: 4668.97
... A57: 44553 | B57: 4725.79
A58: 44554
A59: 44557 | B59: 4791.19
A60: 44558 | B60: 4786.35
A61: 44559 | B61: 4793.06
A62: 44560 | B62: 4778.73
A63: 44561 | B63: 4766.18
A64: 44564 | B64: 4796.56
A65: 44565 | B65: 4793.54
A66: 44566 | B66: 4700.58
...

Sheet 401K_Calculator
A1: 401(k) Retirement Calculator
A3: Current Retirement Balance | B3: 1000 | D3: Monthly Employee Contribution | E3: =B4*B5/12 -> 400 | G3: Year | H3: Projected Balance
A4: Annual Salary | B4: 80000 | D4: Monthly Employer Contribution | E4: =B4*B6/12 -> 200 | G4: 0 | H4: =IF(ISNUMBER(G4),FV($B$7/12,G4*12,-$E$5,-$B$3),"") -> 1000
A5: Employee Contribution (%) | B5: 0.06 | D5: Total Monthly Contribution | E5: =SUM(E3:E4) -> 600 | G5: =IF(G4<$B$8,G4+1,"") -> 1 | H5: =IF(ISNUMBER(G5),FV($B$7/12,G5*12,-$E$5,-$B$3),"") -> 8507.8413
A6: Employer Match (% of Salary) | B6: 0.03 | G6: =IF(G5<$B$8,G5+1,"") -> 2 | H6: =IF(ISNUMBER(G6),FV($B$7/12,G6*12,-$E$5,-$B$3),"") -> 16558.425
A7: Expected Annual Return | B7: 0.07 | D7: Projected Retirement Balance | E7: =FV(B7/12,B8*12,-E5,-B3) -> 316594.73 | G7: =IF(G6<$B$8,G6+1,"") -> 3 | H7: =IF(ISNUMBER(G7),FV($B$7/12,G7*12,-$E$5,-$B$3),"") -> 25190.986
A8: Years Until Retirement | B8: 20 | D8: Total Money Contributed | E8: =B3+(E5*B8*12) -> 145000 | G8: =IF(G7<$B$8,G7+1,"") -> 4 | H8: =IF(ISNUMBER(G8),FV($B$7/12,G8*12,-$E$5,-$B$3),"") -> 34447.596
D9: Projected Investment Growth | E9: =E7-E8 -> 171594.73 | G9: =IF(G8<$B$8,G8+1,"") -> 5 | H9: =IF(ISNUMBER(G9),FV($B$7/12,G9*12,-$E$5,-$B$3),"") -> 44373.366
G10: =IF(G9<$B$8,G9+1,"") -> 6 | H10: =IF(ISNUMBER(G10),FV($B$7/12,G10*12,-$E$5,-$B$3),"") -> 55016.672
G11: =IF(G10<$B$8,G10+1,"") -> 7 | H11: =IF(ISNUMBER(G11),FV($B$7/12,G11*12,-$E$5,-$B$3),"") -> 66429.382
G12: =IF(G11<$B$8,G11+1,"") -> 8 | H12: =IF(ISNUMBER(G12),FV($B$7/12,G12*12,-$E$5,-$B$3),"") -> 78667.119
G13: =IF(G12<$B$8,G12+1,"") -> 9 | H13: =IF(ISNUMBER(G13),FV($B$7/12,G13*12,-$E$5,-$B$3),"") -> 91789.523
G14: =IF(G13<$B$8,G13+1,"") -> 10 | H14: =IF(ISNUMBER(G14),FV($B$7/12,G14*12,-$E$5,-$B$3),"") -> 105860.55
G15: =IF(G14<$B$8,G14+1,"") -> 11 | H15: =IF(ISNUMBER(G15),FV($B$7/12,G15*12,-$E$5,-$B$3),"") -> 120948.76
G16: =IF(G15<$B$8,G15+1,"") -> 12 | H16: =IF(ISNUMBER(G16),FV($B$7/12,G16*12,-$E$5,-$B$3),"") -> 137127.71
G17: =IF(G16<$B$8,G16+1,"") -> 13 | H17: =IF(ISNUMBER(G17),FV($B$7/12,G17*12,-$E$5,-$B$3),"") -> 154476.24
G18: =IF(G17<$B$8,G17+1,"") -> 14 | H18: =IF(ISNUMBER(G18),FV($B$7/12,G18*12,-$E$5,-$B$3),"") -> 173078.89
G19: =IF(G18<$B$8,G18+1,"") -> 15 | H19: =IF(ISNUMBER(G19),FV($B$7/12,G19*12,-$E$5,-$B$3),"") -> 193026.32
G20: =IF(G19<$B$8,G19+1,"") -> 16 | H20: =IF(ISNUMBER(G20),FV($B$7/12,G20*12,-$E$5,-$B$3),"") -> 214415.76
G21: =IF(G20<$B$8,G20+1,"") -> 17 | H21: =IF(ISNUMBER(G21),FV($B$7/12,G21*12,-$E$5,-$B$3),"") -> 237351.45
... G54: =IF(G53<$B$8,G53+1,"") | H54: =IF(ISNUMBER(G54),FV($B$7/12,G54*12,-$E$5,-$B$3),"")
